Workbook
Name BoxName: 'REF - System & Subsystem'!$J$2:$J$1000
Name Chassis: 'REF - System & Subsystem'!$K:$K
Name Components: 'REF - System & Subsystem'!$E:$F
Name DO_9476: 'REF - Interface Cards'!$N$3:$O$30
Name Interface_Cards: 'REF - System & Subsystem'!$L:$L
Name InterfaceCards: 'REF - Interface Cards'!$B:$D
Name IO_Types: 'REF - System & Subsystem'!$M:$M
Name Locations: 'REF - System & Subsystem'!$I:$I
Name Metrics: 'REF - System & Subsystem'!$G:$H
Name Subsystems: 'REF - System & Subsystem'!$C:$D
Name Systems: 'REF - System & Subsystem'!$A:$B
Name Units: 'REF - System & Subsystem'!$N:$N

Sheet Version Control
A1: =HYPERLINK("https://docs.google.com/spreadsheets/d/1aywNd0p-7cme4XnVfCwUuuSuC4CAVWI5jEUNxNGpBUw/edit?usp=sharing","UPDATE THE MAIN RELEASE TRACKING SHEET WHEN MAKING AN ADDITION HERE") -> UPDATE THE MAIN RELEASE TRACKING SHEET WHEN MAKING AN ADDITION HERE
A2: Book | B2: Drawing/Document Number | C2: Document Name | D2: Revision | E2: Release Date | F2: Sent to | H2: Review Completed | M2: MARS Review Completed | N2: Released For Construction | O2: Date Released
G3: Notes | H3: DS | I3: JO | J3: SP | K3: TS | L3: SB
B4: CNTRL-1 | C4: LC2 IO | D4: A1 | E4: 43480 | F4: Aaron Kuipers, Walter Taraila, Nick Counts, Rickie Smith | I4: Y
B5: CNTRL-1 | C5: LC2 IO | D5: A2 | E5: 43486 | F5: Aaron Kuipers, Walter Taraila, Nick Counts, Rickie Smith | I5: Y
B6: CNTRL-1 | C6: LC2 IO | D6: A3 | E6: 43489 | F6: Aaron Kuipers, Walter Taraila, Nick Counts, Rickie Smith | H6: Y | I6: Y
B7: CNTRL-1 | C7: LC2 IO | D7: A4 | E7: 43507 | F7: In house | G7: Updated Sheet due to the change in the IO grouping
B8: CNTRL-1 | C8: LC2 IO | D8: A5 | E8: 43550 | F8: In house

Sheet Channel List
A1: I/O Code | B1: IO Code Number | C1: NEXUS Description | D1: Description | E1: End Device/P&ID Designator | F1: System | G1: Subsystem | H1: End Device Type | I1: IO Type | J1: Chassis | K1: Metric | L1: Units | M1: Ops Criticality (Crititical channels will be mode gated) | N1: Failure Worst Case Effect | O1: Failure Worst Case Severity | P1: Safety review needed
A2: =CONCATENATE(VLOOKUP(F2,Systems,2,FALSE),"-",VLOOKUP(G2,Subsystems,2,FALSE),"-",VLOOKUP(H2,Components,2,FALSE),"-",VLOOKUP(K2,Metrics,2,FALSE),"-",B2) -> AG-HF-DVL-Pos-1 | B2: 1 | C2: =_xlfn.TEXTJOIN("", TRUE, "[", E2,"] ",D2) -> [04C346] Stage 1 Anti-Geysering High Flow Valve - Cmd | D2: Stage 1 Anti-Geysering High Flow Valve - Cmd | E2: 04C346 | F2: Anti-Geysering | G2: High Flow | H2: Discrete Valve | I2: Digital Output (24V) | K2: Valve Position | L2: True/False | P2: FALSE
A3: =CONCATENATE(VLOOKUP(F3,Systems,2,FALSE),"-",VLOOKUP(G3,Subsystems,2,FALSE),"-",VLOOKUP(H3,Components,2,FALSE),"-",VLOOKUP(K3,Metrics,2,FALSE),"-",B3) -> AG-S1U-PRS-Ps-2 | B3: 2 | C3: =_xlfn.TEXTJOIN("", TRUE, "[", E3,"] ",D3) -> [04C932] Stage 1 Anti-Geysering Delivery Pressure | D3: Stage 1 Anti-Geysering Delivery Pressure | E3: 04C932 | F3: Anti-Geysering | G3: Stage 1 Umbilical | H3: Pressure Sensor | I3: Analog Input (4-20mA, sinking) | K3: Pressure | L3: PSI-G | P3: FALSE
A4: =CONCATENATE(VLOOKUP(F4,Systems,2,FALSE),"-",VLOOKUP(G4,Subsystems,2,FALSE),"-",VLOOKUP(H4,Components,2,FALSE),"-",VLOOKUP(K4,Metrics,2,FALSE),"-",B4) -> AG-S2U-PRS-Ps-3 | B4: 3 | C4: =_xlfn.TEXTJOIN("", TRUE, "[", E4,"] ",D4) -> [04C930] Stage 2 Anti Geysering Delivery Pressure | D4: Stage 2 Anti Geysering Delivery Pressure | E4: 04C930 | F4: Anti-Geysering | G4: Stage 2 Umbilical | H4: Pressure Sensor | I4: Analog Input (4-20mA, sinking) | K4: Pressure | L4: PSI-G | P4: FALSE
A5: =CONCATENATE(VLOOKUP(F5,Systems,2,FALSE),"-",VLOOKUP(G5,Subsystems,2,FALSE),"-",VLOOKUP(H5,Components,2,FALSE),"-",VLOOKUP(K5,Metrics,2,FALSE),"-",B5) -> AG-HF-DVL-Pos-4 | B5: 4 | C5: =_xlfn.TEXTJOIN("", TRUE, "[", E5,"] ",D5) -> [04C386] Stage 2 Anti-Geysering High Flow Valve Controller | D5: Stage 2 Anti-Geysering High Flow Valve Controller | E5: 04C386 | F5: Anti-Geysering | G5: High Flow | H5: Discrete Valve | I5: Digital Output (24V) | K5: Valve Position | L5: True/False | P5: FALSE
A6: =CONCATENATE(VLOOKUP(F6,Systems,2,FALSE),"-",VLOOKUP(G6,Subsystems,2,FALSE),"-",VLOOKUP(H6,Components,2,FALSE),"-",VLOOKUP(K6,Metrics,2,FALSE),"-",B6) -> AG-LF-DVL-Pos-5 | B6: 5 | C6: =_xlfn.TEXTJOIN("", TRUE, "[", E6,"] ",D6) -> [04C345] Stage 1 Anti-Geysering Low Flow Valve - Cmd | D6: Stage 1 Anti-Geysering Low Flow Valve - Cmd | E6: 04C345 | F6: Anti-Geysering | G6: Low Flow | H6: Discrete Valve | I6: Digital Output (24V) | K6: Valve Position | L6: True/False | P6: FALSE
A7: =CONCATENATE(VLOOKUP(F7,Systems,2,FALSE),"-",VLOOKUP(G7,Subsystems,2,FALSE),"-",VLOOKUP(H7,Components,2,FALSE),"-",VLOOKUP(K7,Metrics,2,FALSE),"-",B7) -> AG-LF-DVL-Pos-6 | B7: 6 | C7: =_xlfn.TEXTJOIN("", TRUE, "[", E7,"] ",D7) -> [04C385] Stage 2 Anti-Geysering Low Flow Valve Controller | D7: Stage 2 Anti-Geysering Low Flow Valve Controller | E7: 04C385 | F7: Anti-Geysering | G7: Low Flow | H7: Discrete Valve | I7: Digital Output (24V) | K7: Valve Position | L7: True/False | P7: FALSE
A8: =CONCATENATE(VLOOKUP(F8,Systems,2,FALSE),"-",VLOOKUP(G8,Subsystems,2,FALSE),"-",VLOOKUP(H8,Components,2,FALSE),"-",VLOOKUP(K8,Metrics,2,FALSE),"-",B8) -> ASP--AxCt-ST-7 | B8: 7 | C8: =_xlfn.TEXTJOIN("", TRUE, "[", E8,"] ",D8) -> [FTS-ISO(A)] Power Isolation Contactor FTS-ISO(A) | D8: Power Isolation Contactor FTS-ISO(A) | E8: FTS-ISO(A) | F8: Avionics Shore Power | G8: BLANK | H8: Auxiliary Contact | I8: Digital Input (24V) | K8: State | L8: True/False | P8: FALSE
A9: =CONCATENATE(VLOOKUP(F9,Systems,2,FALSE),"-",VLOOKUP(G9,Subsystems,2,FALSE),"-",VLOOKUP(H9,Components,2,FALSE),"-",VLOOKUP(K9,Metrics,2,FALSE),"-",B9) -> ASP--AxCt-ST-8 | B9: 8 | C9: =_xlfn.TEXTJOIN("", TRUE, "[", E9,"] ",D9) -> [S3-ISO(A)] Power Isolation Contactor S3-ISO(A) | D9: Power Isolation Contactor S3-ISO(A) | E9: S3-ISO(A) | F9: Avionics Shore Power | G9: BLANK | H9: Auxiliary Contact | I9: Digital Input (24V) | K9: State | L9: True/False | P9: FALSE
A10: =CONCATENATE(VLOOKUP(F10,Systems,2,FALSE),"-",VLOOKUP(G10,Subsystems,2,FALSE),"-",VLOOKUP(H10,Components,2,FALSE),"-",VLOOKUP(K10,Metrics,2,FALSE),"-",B10) -> ASP--AxCt-ST-9 | B10: 9 | C10: =_xlfn.TEXTJOIN("", TRUE, "[", E10,"] ",D10) -> [S2L-ISO(A)] Power Isolation Contactor S2L-ISO(A) | D10: Power Isolation Contactor S2L-ISO(A) | E10: S2L-ISO(A) | F10: Avionics Shore Power | G10: BLANK | H10: Auxiliary Contact | I10: Digital Input (24V) | K10: State | L10: True/False | P10: FALSE
A11: =CONCATENATE(VLOOKUP(F11,Systems,2,FALSE),"-",VLOOKUP(G11,Subsystems,2,FALSE),"-",VLOOKUP(H11,Components,2,FALSE),"-",VLOOKUP(K11,Metrics,2,FALSE),"-",B11) -> ASP--AxCt-ST-10 | B11: 10 | C11: =_xlfn.TEXTJOIN("", TRUE, "[", E11,"] ",D11) -> [S1U-ISO(A)] Power Isolation Contactor S1U-ISO(A) | D11: Power Isolation Contactor S1U-ISO(A) | E11: S1U-ISO(A) | F11: Avionics Shore Power | G11: BLANK | H11: Auxiliary Contact | I11: Digital Input (24V) | K11: State | L11: True/False | P11: FALSE
A12: =CONCATENATE(VLOOKUP(F12,Systems,2,FALSE),"-",VLOOKUP(G12,Subsystems,2,FALSE),"-",VLOOKUP(H12,Components,2,FALSE),"-",VLOOKUP(K12,Metrics,2,FALSE),"-",B12) -> ASP--AxCt-ST-11 | B12: 11 | C12: =_xlfn.TEXTJOIN("", TRUE, "[", E12,"] ",D12) -> [S1L-ISO(A)] Power Isolation Contactor S1L-ISO(A) | D12: Power Isolation Contactor S1L-ISO(A) | E12: S1L-ISO(A) | F12: Avionics Shore Power | G12: BLANK | H12: Auxiliary Contact | I12: Digital Input (24V) | K12: State | L12: True/False | P12: FALSE
A13: =CONCATENATE(VLOOKUP(F13,Systems,2,FALSE),"-",VLOOKUP(G13,Subsystems,2,FALSE),"-",VLOOKUP(H13,Components,2,FALSE),"-",VLOOKUP(K13,Metrics,2,FALSE),"-",B13) -> ASP--AxCt-ST-12 | B13: 12 | C13: =_xlfn.TEXTJOIN("", TRUE, "[", E13,"] ",D13) -> [FTS-ISO(B)] Power Isolation Contactor FTS-ISO(B) | D13: Power Isolation Contactor FTS-ISO(B) | E13: FTS-ISO(B) | F13: Avionics Shore Power | G13: BLANK | H13: Auxiliary Contact | I13: Digital Input (24V) | K13: State | L13: True/False | P13: FALSE
... A33: =CONCATENATE(VLOOKUP(F33,Systems,2,FALSE),"-",VLOOKUP(G33,Subsystems,2,FALSE),"-",VLOOKUP(H33,Components,2,FALSE),"-",VLOOKUP(K33,Metrics,2,FALSE),"-",B33) -> CPWR-RST-FX-CD-32 | B33: 32 | C33: =_xlfn.TEXTJOIN("", TRUE, "[", E33,"] ",D33) -> [ISO-EN PSU B] Rocket Power Isolation Enable PSU B | D33: Rocket Power Isolation Enable PSU B | E33: ISO-EN PSU B | F33: Control Power | G33: Reset | H33: Fuse | I33: Digital Output (24V) | K33: Current Draw | L33: True/False | P33: FALSE
A34: =CONCATENATE(VLOOKUP(F34,Systems,2,FALSE),"-",VLOOKUP(G34,Subsystems,2,FALSE),"-",VLOOKUP(H34,Components,2,FALSE),"-",VLOOKUP(K34,Metrics,2,FALSE),"-",B34) -> CPWR-RST-FX-CD-33 | B34: 33 | C34: =_xlfn.TEXTJOIN("", TRUE, "[", E34,"] ",D34) -> [STP-CB6RST] SITOP's Reset CB6 | D34: SITOP's Reset CB6 | E34: STP-CB6RST | F34: Control Power | G34: Reset | H34: Fuse | I34: Digital Output (24V) | J34: N5 | K34: Current Draw | L34: True/False | P34: FALSE
A35: =CONCATENATE(VLOOKUP(F35,Systems,2,FALSE),"-",VLOOKUP(G35,Subsystems,2,FALSE),"-",VLOOKUP(H35,Components,2,FALSE),"-",VLOOKUP(K35,Metrics,2,FALSE),"-",B35) -> CPWR-OL-FX-CD-34 | B35: 34 | C35: =_xlfn.TEXTJOIN("", TRUE, "[", E35,"] ",D35) -> [SITOP15] SITOP15 Power power supply Trip | D35: SITOP15 Power power supply Trip | E35: SITOP15 | F35: Control Power | G35: Current Overload | H35: Fuse | I35: Digital Input (24V) | K35: Current Draw | L35: True/False | P35: FALSE
A36: =CONCATENATE(VLOOKUP(F36,Systems,2,FALSE),"-",VLOOKUP(G36,Subsystems,2,FALSE),"-",VLOOKUP(H36,Components,2,FALSE),"-",VLOOKUP(K36,Metrics,2,FALSE),"-",B36) -> CPWR-OL-FX-CD-35 | B36: 35 | C36: =_xlfn.TEXTJOIN("", TRUE, "[", E36,"] ",D36) -> [SITOP3] SITOP3 Power supply Trip | D36: SITOP3 Power supply Trip | E36: SITOP3 | F36: Control Power | G36: Current Overload | H36: Fuse | I36: Digital Input (24V) | K36: Current Draw | L36: True/False | P36: FALSE
A37: =CONCATENATE(VLOOKUP(F37,Systems,2,FALSE),"-",VLOOKUP(G37,Subsystems,2,FALSE),"-",VLOOKUP(H37,Components,2,FALSE),"-",VLOOKUP(K37,Metrics,2,FALSE),"-",B37) -> CPWR-OL-FX-CD-36 | B37: 36 | C37: =_xlfn.TEXTJOIN("", TRUE, "[", E37,"] ",D37) -> [SITOP5] SITOP5 Power supply Trip | D37: SITOP5 Power supply Trip | E37: SITOP5 | F37: Control Power | G37: Current Overload | H37: Fuse | I37: Digital Input (24V) | K37: Current Draw | L37: True/False | P37: FALSE
A38: =CONCATENATE(VLOOKUP(F38,Systems,2,FALSE),"-",VLOOKUP(G38,Subsystems,2,FALSE),"-",VLOOKUP(H38,Components,2,FALSE),"-",VLOOKUP(K38,Metrics,2,FALSE),"-",B38) -> CPWR-OL-FX-CD-37 | B38: 37 | C38: =_xlfn.TEXTJOIN("", TRUE, "[", E38,"] ",D38) -> [SITOP10] SITOP10 Power supply Trip | D38: SITOP10 Power supply Trip | E38: SITOP10 | F38: Control Power | G38: Current Overload | H38: Fuse | I38: Digital Input (24V) | K38: Current Draw | L38: True/False | P38: FALSE
A39: =CONCATENATE(VLOOKUP(F39,Systems,2,FALSE),"-",VLOOKUP(G39,Subsystems,2,FALSE),"-",VLOOKUP(H39,Components,2,FALSE),"-",VLOOKUP(K39,Metrics,2,FALSE),"-",B39) -> CPWR-OL-FX-CD-38 | B39: 38 | C39: =_xlfn.TEXTJOIN("", TRUE, "[", E39,"] ",D39) -> [SITOP8] SITOP8 Power supply Trip | D39: SITOP8 Power supply Trip | E39: SITOP8 | F39: Control Power | G39: Current Overload | H39: Fuse | I39: Digital Input (24V) | K39: Current Draw | L39: True/False | P39: FALSE
A40: =CONCATENATE(VLOOKUP(F40,Systems,2,FALSE),"-",VLOOKUP(G40,Subsystems,2,FALSE),"-",VLOOKUP(H40,Components,2,FALSE),"-",VLOOKUP(K40,Metrics,2,FALSE),"-",B40) -> CPWR-OL-FX-CD-39 | B40: 39 | C40: =_xlfn.TEXTJOIN("", TRUE, "[", E40,"] ",D40) -> [SITOP12] SITOP12 Power supply trip | D40: SITOP12 Power supply trip | E40: SITOP12 | F40: Control Power | G40: Current Overload | H40: Fuse | I40: Digital Input (24V) | K40: Current Draw | L40: True/False | P40: FALSE
A41: =CONCATENATE(VLOOKUP(F41,Systems,2,FALSE),"-",VLOOKUP(G41,Subsystems,2,FALSE),"-",VLOOKUP(H41,Components,2,FALSE),"-",VLOOKUP(K41,Metrics,2,FALSE),"-",B41) -> CPWR-OL-FX-CD-40 | B41: 40 | C41: =_xlfn.TEXTJOIN("", TRUE, "[", E41,"] ",D41) -> [SITOP14] SITOP14 Power power supply Trip | D41: SITOP14 Power power supply Trip | E41: SITOP14 | F41: Control Power | G41: Current Overload | H41: Fuse | I41: Digital Input (24V) | K41: Current Draw | L41: True/False | P41: FALSE
A42: =CONCATENATE(VLOOKUP(F42,Systems,2,FALSE),"-",VLOOKUP(G42,Subsystems,2,FALSE),"-",VLOOKUP(H42,Components,2,FALSE),"-",VLOOKUP(K42,Metrics,2,FALSE),"-",B42) -> CPWR-RST-FX-CD-41 | B42: 41 | C42: =_xlfn.TEXTJOIN("", TRUE, "[", E42,"] ",D42) -> [STP-CB8RST] SITOP's Reset CB8 | D42: SITOP's Reset CB8 | E42: STP-CB8RST | F42: Control Power | G42: Reset | H42: Fuse | I42: Digital Output (24V) | J42: C2 | K42: Current Draw | L42: True/False | P42: FALSE
A43: =CONCATENATE(VLOOKUP(F43,Systems,2,FALSE),"-",VLOOKUP(G43,Subsystems,2,FALSE),"-",VLOOKUP(H43,Components,2,FALSE),"-",VLOOKUP(K43,Metrics,2,FALSE),"-",B43) -> CPWR-RST-FX-CD-42 | B43: 42 | C43: =_xlfn.TEXTJOIN("", TRUE, "[", E43,"] ",D43) -> [STP-RST] All SITOP's Reset | D43: All SITOP's Reset | E43: STP-RST | F43: Control Power | G43: Reset | H43: Fuse | I43: Digital Output (24V) | K43: Current Draw | L43: True/False | P43: FALSE
A44: =CONCATENATE(VLOOKUP(F44,Systems,2,FALSE),"-",VLOOKUP(G44,Subsystems,2,FALSE),"-",VLOOKUP(H44,Components,2,FALSE),"-",VLOOKUP(K44,Metrics,2,FALSE),"-",B44) -> CPWR-OL-FX-CD-43 | B44: 43 | C44: =_xlfn.TEXTJOIN("", TRUE, "[", E44,"] ",D44) -> [SITOP9] SITOP9 Power supply Trip | D44: SITOP9 Power supply Trip | E44: SITOP9 | F44: Control Power | G44: Current Overload | H44: Fuse | I44: Digital Input (24V) | K44: Current Draw | L44: True/False | P44: FALSE
A45: =CONCATENATE(VLOOKUP(F45,Systems,2,FALSE),"-",VLOOKUP(G45,Subsystems,2,FALSE),"-",VLOOKUP(H45,Components,2,FALSE),"-",VLOOKUP(K45,Metrics,2,FALSE),"-",B45) -> HVBH-ESTOP-SAFTEY-RELAY-ST-44 | B45: 44 | C45: =_xlfn.TEXTJOIN("", TRUE, "[", E45,"] ",D45) -> [HVHSUP] HVBH E-Stop Status | D45: HVBH E-Stop Status | E45: HVHSUP | F45: High Voltage Battery Heaters | G45: E-Stop | H45: Safety Relay | I45: Digital Input (24V) | K45: State | L45: True/False | P45: FALSE
A46: =CONCATENATE(VLOOKUP(F46,Systems,2,FALSE),"-",VLOOKUP(G46,Subsystems,2,FALSE),"-",VLOOKUP(H46,Components,2,FALSE),"-",VLOOKUP(K46,Metrics,2,FALSE),"-",B46) -> CPWR-RST-FX-CD-45 | B46: 45 | C46: =_xlfn.TEXTJOIN("", TRUE, "[", E46,"] ",D46) -> [CPWR-RST-FX-CD-45] 24V Safety E-stop | D46: 24V Safety E-stop | E46: CPWR-RST-FX-CD-45 | F46: Control Power | G46: Reset | H46: Fuse | I46: Digital Output (24V) | K46: Current Draw | L46: True/False | P46: FALSE
A47: =CONCATENATE(VLOOKUP(F47,Systems,2,FALSE),"-",VLOOKUP(G47,Subsystems,2,FALSE),"-",VLOOKUP(H47,Components,2,FALSE),"-",VLOOKUP(K47,Metrics,2,FALSE),"-",B47) -> CPWR-OL-FX-CD-46 | B47: 46 | C47: =_xlfn.TEXTJOIN("", TRUE, "[", E47,"] ",D47) -> [SITOP11] SITOP11 Power supply trip | D47: SITOP11 Power supply trip | E47: SITOP11 | F47: Control Power | G47: Current Overload | H47: Fuse | I47: Digital Input (24V) | K47: Current Draw | L47: True/False | P47: FALSE
A48: =CONCATENATE(VLOOKUP(F48,Systems,2,FALSE),"-",VLOOKUP(G48,Subsystems,2,FALSE),"-",VLOOKUP(H48,Components,2,FALSE),"-",VLOOKUP(K48,Metrics,2,FALSE),"-",B48) -> GHe-STR-DVL-Pos-47 | B48: 47 | C48: =_xlfn.TEXTJOIN("", TRUE, "[", E48,"] ",D48) -> [04C342] GHe Source Pressure Supply Backup Discrete Valve Controller | D48: GHe Source Pressure Supply Backup Discrete Valve Controller | E48: 04C342 | F48: Gas Helium | G48: Storage | H48: Discrete Valve | I48: Digital Output (24V) | K48: Valve Position | L48: True/False | P48: FALSE
A49: =CONCATENATE(VLOOKUP(F49,Systems,2,FALSE),"-",VLOOKUP(G49,Subsystems,2,FALSE),"-",VLOOKUP(H49,Components,2,FALSE),"-",VLOOKUP(K49,Metrics,2,FALSE),"-",B49) -> GHe-STR-PRS-Ps-48 | B49: 48 | C49: =_xlfn.TEXTJOIN("", TRUE, "[", E49,"] ",D49) -> [04C924] Gas Helium Bottle Pressure | D49: Gas Helium Bottle Pressure | E49: 04C924 | F49: Gas Helium | G49: Storage | H49: Pressure Sensor | I49: Analog Input (4-20mA, sinking) | K49: Pressure | L49: PSI-G | P49: FALSE
A50: =CONCATENATE(VLOOKUP(F50,Systems,2,FALSE),"-",VLOOKUP(G50,Subsystems,2,FALSE),"-",VLOOKUP(H50,Components,2,FALSE),"-",VLOOKUP(K50,Metrics,2,FALSE),"-",B50) -> GHe-STR-PRS-Ps-49 | B50: 49 | C50: =_xlfn.TEXTJOIN("", TRUE, "[", E50,"] ",D50) -> [04C925] Gas Helium Regulator Pressure | D50: Gas Helium Regulator Pressure | E50: 04C925 | F50: Gas Helium | G50: Storage | H50: Pressure Sensor | I50: Analog Input (4-20mA, sinking) | K50: Pressure | L50: PSI-G | P50: FALSE
A51: =CONCATENATE(VLOOKUP(F51,Systems,2,FALSE),"-",VLOOKUP(G51,Subsystems,2,FALSE),"-",VLOOKUP(H51,Components,2,FALSE),"-",VLOOKUP(K51,Metrics,2,FALSE),"-",B51) -> GHe-STR-DVL-Pos-50 | B51: 50 | C51: =_xlfn.TEXTJOIN("", TRUE, "[", E51,"] ",D51) -> [04C343] Store Helium Back up | D51: Store Helium Back up | E51: 04C343 | F51: Gas Helium | G51: Storage | H51: Discrete Valve | I51: Digital Output (24V) | K51: Valve Position | L51: True/False | P51: FALSE
A52: =CONCATENATE(VLOOKUP(F52,Systems,2,FALSE),"-",VLOOKUP(G52,Subsystems,2,FALSE),"-",VLOOKUP(H52,Components,2,FALSE),"-",VLOOKUP(K52,Metrics,2,FALSE),"-",B52) -> GN2-STR-PRS-Ps-51 | B52: 51 | C52: =_xlfn.TEXTJOIN("", TRUE, "[", E52,"] ",D52) -> [05C941] GN2 Utility Skid Ejection Regulator Pressure | D52: GN2 Utility Skid Ejection Regulator Pressure | E52: 05C941 | F52: Gas Nitrogen | G52: Storage | H52: Pressure Sensor | I52: Analog Input (4-20mA, sinking) | K52: Pressure | L52: PSI-G | P52: FALSE
A53: =CONCATENATE(VLOOKUP(F53,Systems,2,FALSE),"-",VLOOKUP(G53,Subsystems,2,FALSE),"-",VLOOKUP(H53,Components,2,FALSE),"-",VLOOKUP(K53,Metrics,2,FALSE),"-",B53) -> GN2-STR-PRS-Ps-52 | B53: 52 | C53: =_xlfn.TEXTJOIN("", TRUE, "[", E53,"] ",D53) -> [05C942] GN2 Utility Skid High Flow Regulator Pressure | D53: GN2 Utility Skid High Flow Regulator Pressure | E53: 05C942 | F53: Gas Nitrogen | G53: Storage | H53: Pressure Sensor | I53: Analog Input (4-20mA, sinking) | K53: Pressure | L53: PSI-G | P53: FALSE
A54: =CONCATENATE(VLOOKUP(F54,Systems,2,FALSE),"-",VLOOKUP(G54,Subsystems,2,FALSE),"-",VLOOKUP(H54,Components,2,FALSE),"-",VLOOKUP(K54,Metrics,2,FALSE),"-",B54) -> GN2-PRG-PRS-Ps-53 | B54: 53 | C54: =_xlfn.TEXTJOIN("", TRUE, "[", E54,"] ",D54) -> [05C943] HVAC regulator pressure | D54: HVAC regulator pressure | E54: 05C943 | F54: Gas Nitrogen | G54: Purge | H54: Pressure Sensor | I54: Analog Input (4-20mA, sinking) | K54: Pressure | L54: PSI-G | P54: FALSE
... A56: =CONCATENATE(VLOOKUP(F56,Systems,2,FALSE),"-",VLOOKUP(G56,Subsystems,2,FALSE),"-",VLOOKUP(H56,Components,2,FALSE),"-",VLOOKUP(K56,Metrics,2,FALSE),"-",B56) -> GN2-STR-PRS-Ps-55 | B56: 55 | C56: =_xlfn.TEXTJOIN("", TRUE, "[", E56,"] ",D56) -> [05C940] GN2 Utility Skid Supply Pressure | D56: GN2 Utility Skid Supply Pressure | E56: 05C940 | F56: Gas Nitrogen | G56: Storage | H56: Pressure Sensor | I56: Analog Input (4-20mA, sinking) | K56: Pressure | L56: PSI-G | P56: FALSE
A57: =CONCATENATE(VLOOKUP(F57,Systems,2,FALSE),"-",VLOOKUP(G57,Subsystems,2,FALSE),"-",VLOOKUP(H57,Components,2,FALSE),"-",VLOOKUP(K57,Metrics,2,FALSE),"-",B57) -> HVBH-HSE-SSR-B-56 | B57: 56 | C57: =_xlfn.TEXTJOIN("", TRUE, "[", E57,"] ",D57) -> [HVBH-HSE-SSR-B-56] Battery Heater Enable-H01 | D57: Battery Heater Enable-H01 | E57: =A57 -> HVBH-HSE-SSR-B-56 | F57: High Voltage Battery Heaters | G57: Heater Select Enable | H57: Solid State Relay | I57: Digital Output (24V) | K57: Bool | L57: True/False | P57: FALSE
A58: =CONCATENATE(VLOOKUP(F58,Systems,2,FALSE),"-",VLOOKUP(G58,Subsystems,2,FALSE),"-",VLOOKUP(H58,Components,2,FALSE),"-",VLOOKUP(K58,Metrics,2,FALSE),"-",B58) -> HVBH-HSE-SSR-B-57 | B58: 57 | C58: =_xlfn.TEXTJOIN("", TRUE, "[", E58,"] ",D58) -> [HVBH-HSE-SSR-B-57] Battery Heater Enable-H02 | D58: Battery Heater Enable-H02 | E58: =A58 -> HVBH-HSE-SSR-B-57 | F58: High Voltage Battery Heaters | G58: Heater Select Enable | H58: Solid State Relay | I58: Digital Output (24V) | K58: Bool | L58: True/False | P58: FALSE
A59: =CONCATENATE(VLOOKUP(F59,Systems,2,FALSE),"-",VLOOKUP(G59,Subsystems,2,FALSE),"-",VLOOKUP(H59,Components,2,FALSE),"-",VLOOKUP(K59,Metrics,2,FALSE),"-",B59) -> HVBH-HSE-SSR-B-58 | B59: 58 | C59: =_xlfn.TEXTJOIN("", TRUE, "[", E59,"] ",D59) -> [HVBH-HSE-SSR-B-58] Battery Heater Enable-H03 | D59: Battery Heater Enable-H03 | E59: =A59 -> HVBH-HSE-SSR-B-58 | F59: High Voltage Battery Heaters | G59: Heater Select Enable | H59: Solid State Relay | I59: Digital Output (24V) | K59: Bool | L59: True/False | P59: FALSE
A60: =CONCATENATE(VLOOKUP(F60,Systems,2,FALSE),"-",VLOOKUP(G60,Subsystems,2,FALSE),"-",VLOOKUP(H60,Components,2,FALSE),"-",VLOOKUP(K60,Metrics,2,FALSE),"-",B60) -> HVBH-HSE-SSR-B-59 | B60: 59 | C60: =_xlfn.TEXTJOIN("", TRUE, "[", E60,"] ",D60) -> [HVBH-HSE-SSR-B-59] Battery Heater Enable-H04 | D60: Battery Heater Enable-H04 | E60: =A60 -> HVBH-HSE-SSR-B-59 | F60: High Voltage Battery Heaters | G60: Heater Select Enable | H60: Solid State Relay | I60: Digital Output (24V) | K60: Bool | L60: True/False | P60: FALSE
...

Sheet SWE InputOutput List
A1: Function | B1: Type | C1: Component | D1: Reference | E1: Address | F1: Mnemonic | G1: Associated macro | H1: Description (English) | I1: User data 1 | J1: User data 2 | K1: Translatable data 1 (English) | L1: Translatable data 2 (English)
A2: ... | B2: Analog PLC output | C2: N1-AO1 | D2: NI 9266 | F2: HYD-LFT-PVL-Pos-150 | G2: <Default>... | H2: Strongback|extend/retract | I2: S9 | J2: S7
A3: ... | B3: Analog PLC output | C3: N1-AO1 | D3: NI 9266 | F3: HYD-LFT-PVL-Pos-151 | G3: <Default>... | H3: Platform tilt | I3: S7 | J3: S5
A4: ... | B4: Analog PLC output | C4: N1-AO1 | D4: NI 9266 | F4: HVAC-FAR-PVL-Pos-98 | G4: <Default>... | H4: ECS GN2 Supply to Payload Umbilical|Proportional Control Valve Controller | I4: 05C351.1
A5: ... | B5: Analog PLC output | C5: N1-AO1 | D5: NI 9266 | F5: HVAC-IS2-PVL-Pos-99 | G5: <Default>... | H5: ECS GN2 Supply to S2 Umbilical|Proportional Control Valve (Top) Controller | I5: 05C352.1
A6: ... | B6: Analog PLC output | C6: N1-AO1 | D6: NI 9266 | F6: HVAC-IS1-PVL-Pos-100 | G6: <Default>... | H6: ECS GN2 Supply to S2 Umbilical|Proportional Control Valve (Bottom) Controller | I6: 05C353.1
A7: ... | B7: Analog PLC output | C7: N1-AO1 | D7: NI 9266 | F7: HVAC-PP-PVL-Pos-101 | G7: <Default>... | H7: ECS GN2 Supply to S1 Umbilical|Proportional Control Valve Controller | I7: 05C354.1
A8: ... | B8: Analog PLC output | C8: N1-AO1 | D8: NI 9266 | F8: HVAC-FAR-PVL-Pos-102 | G8: <Default>... | H8: ECS GN2 LN2 Interface to Payload Umbilical|Line Proportional Control Valve Controller | I8: 03C347.1
A9: ... | B9: Analog PLC output | C9: N1-AO2 | D9: NI 9266 | F9: HVAC-IS2-PVL-Pos-103 | G9: <Default>... | H9: ECS GN2 LN2 Interface to S2 Umbilical Line|Proportional Control Valve Controller | I9: 03C348.1
A10: ... | B10: Analog PLC output | C10: N1-AO2 | D10: NI 9266 | F10: HVAC-IS1-PVL-Pos-104 | G10: <Default>... | H10: ECS GN2 LN2 Interface to S2 Umbilical Line|Proportional Control Valve Controller | I10: 03C349.1
A11: ... | B11: Analog PLC output | C11: N1-AO2 | D11: NI 9266 | F11: HVAC-PP-PVL-Pos-105 | G11: <Default>... | H11: ECS GN2 LN2 Interface to S1 Umbilical Line|Proportional Control Valve Controller | I11: 03C350.1
A12: ... | B12: Analog PLC output | C12: N1-AO1 | D12: NI 9266 | F12: HYD-LFT-PVL-Pos-149 | G12: <Default>... | H12: Top Clamp|Open/Close | I12: S8 | J12: S6
A13: ... | B13: Digital PLC output | C13: C1-DO2 | D13: NI 9476 (D-Sub) | F13: IGN-CH4-DVL-B-286 | G13: <Default>... | H13: CH4 Ignitor Bottle|Supply - EV | I13: 14C317 | J13: 13C301.2
A14: ... | B14: Digital PLC output | C14: C1-DO2 | D14: NI 9476 (D-Sub) | F14: CO2-MN-DVL-B-20 | G14: <Default>... | H14: Primary Discrete|Valve Controller | I14: 13C301.1 | J14: 13C301.1
A15: ... | B15: Digital PLC output | C15: C1-DO2 | D15: NI 9476 (D-Sub) | F15: WD-FTC-DVL-B-447 | G15: <Default>... | H15: Flame Trence Curtain|Valve Controller (FUTURE) | I15: 41C305.1
A16: ... | B16: Digital PLC output | C16: C1-DO2 | D16: NI 9476 (D-Sub) | F16: WD-RB-DVL-B-449 | G16: <Default>... | H16: North Side Rainbirds|Valve Controller | I16: 41C306.2 | J16: 41C306.2
A17: ... | B17: Digital PLC output | C17: C1-DO2 | D17: NI 9476 (D-Sub) | F17: WD-AUX-DVL-B-451 | G17: <Default>... | H17: Discrete Ball Valve Controller | I17: 41C308.1 | J17: 41C308.1
A18: ... | B18: Digital PLC output | C18: C1-DO2 | D18: NI 9476 (D-Sub) | F18: WD-RB-DVL-B-452 | G18: <Default>... | H18: South Side Rainbirds Valve Controller | I18: 41C309.1 | J18: 41C309.1
A19: ... | B19: Digital PLC output | C19: C1-DO2 | D19: NI 9476 (D-Sub) | F19: IGN-GOX-DVL-B-275 | G19: <Default>... | H19: GOX Ignitor Supply|Discrete Valve | I19: 15C310
A20: ... | B20: Digital PLC output | C20: C1-DO2 | D20: NI 9476 (D-Sub) | F20: IGN-GOX-DVL-B-276 | G20: <Default>... | H20: GOX Panel Controlled|Vent Discrete Valve | I20: 15C311
A21: ... | B21: Digital PLC output | C21: C1-DO2 | D21: NI 9476 (D-Sub) | F21: IGN-GOX-DVL-B-277 | G21: <Default>... | H21: GOX Ignitor Purge|Bypass Discrete Valve | I21: 15C312
A22: ... | B22: Digital PLC output | C22: C1-DO2 | D22: NI 9476 (D-Sub) | F22: IGN-GOX-DVL-B-279 | G22: <Default>... | H22: GOX Ignitor Primary|Supply Discrete Valve | I22: 15C313
A23: ... | B23: Digital PLC output | C23: C1-DO2 | D23: NI 9476 (D-Sub) | F23: IGN-GOX-DVL-B-281 | G23: <Default>... | H23: GOX Ignitor Upstream|Vent Return Solenoid | I23: 15C380
A24: ... | B24: Digital PLC output | C24: C1-DO2 | D24: NI 9476 (D-Sub) | F24: IGN-CH4-DVL-B-282 | G24: <Default>... | H24: CH4 Panel Controlled|Vent Discrete Valve | I24: 14C318
A25: ... | B25: Digital PLC output | C25: C1-DO2 | D25: NI 9476 (D-Sub) | F25: IGN-CH4-DVL-B-283 | G25: <Default>... | H25: CH4 Ignitor Purge|Bypass Discrete Valve | I25: 14C319
A26: ... | B26: Digital PLC output | C26: C1-DO2 | D26: NI 9476 (D-Sub) | F26: IGN-CH4-DVL-B-284 | G26: <Default>... | H26: CH4 Primary Ignitor|Supply Discrete Valve | I26: 14C320
A27: ... | B27: Digital PLC output | C27: C1-DO1 | D27: NI 9476 (D-Sub) | F27: HYD-LFT-DVL-B-155 | G27: <Default>... | H27: Back up S10|top clamp open | I27: S10.1 | J27: S6.1
A28: ... | B28: Digital PLC output | C28: C1-DO1 | D28: NI 9476 (D-Sub) | F28: HYD-LFT-DVL-B-156 | G28: <Default>... | H28: Back up S10|top clamp close | I28: S10.2 | J28: S6.2
A29: ... | B29: Digital PLC output | C29: C1-DO1 | D29: NI 9476 (D-Sub) | F29: HYD-LFT-DVL-B-157 | G29: <Default>... | H29: Back up S13|strongback retract | I29: S13.1 | J29: S7.1
A30: ... | B30: Digital PLC output | C30: C1-DO1 | D30: NI 9476 (D-Sub) | F30: HYD-LFT-DVL-B-158 | G30: <Default>... | H30: Back up S13|strongback engage | I30: S13.2 | J30: S7.2
A31: ... | B31: Digital PLC output | C31: C1-DO1 | D31: NI 9476 (D-Sub) | F31: HYD-LFT-DVL-B-159 | G31: <Default>... | H31: S8 changeover|to backup | I31: S11, S12 | J31: S6.3, S6.4
A32: ... | B32: Digital PLC output | C32: C1-DO1 | D32: NI 9476 (D-Sub) | F32: HYD-LFT-DVL-B-160 | G32: <Default>... | H32: S9 change over|to back up | I32: S14, S15 | J32: S7.3, S7.4
A33: ... | B33: Digital PLC output | C33: C1-DO1 | D33: NI 9476 (D-Sub) | F33: HYD-HD-DVL-B-164 | G33: <Default>... | H33: High Speed Retract|HD1 | I33: S17 | J33: S8.1
A34: ... | B34: Digital PLC output | C34: C1-DO1 | D34: NI 9476 (D-Sub) | F34: HYD-HD-DVL-B-165 | G34: <Default>... | H34: High Speed Retract|HD2 | I34: S19 | J34: S8.3
A35: ... | B35: Digital PLC output | C35: C1-DO1 | D35: NI 9476 (D-Sub) | F35: HYD-HD-DVL-B-166 | G35: <Default>... | H35: High Speed Retract|HD3 | I35: S21 | J35: S8.5
A36: ... | B36: Digital PLC output | C36: C1-DO1 | D36: NI 9476 (D-Sub) | F36: HYD-HD-DVL-B-167 | G36: <Default>... | H36: High Speed Retract|HD4 | I36: S23 | J36: S8.7
A37: ... | B37: Digital PLC output | C37: C1-DO2 | D37: NI 9476 (D-Sub) | F37: HYD-HD-SSR-B-169 | G37: <Default>... | H37: Secondary High Speed|Retract enable | I37: HYD-HD-SSR-B-169
A38: ... | B38: Digital PLC output | C38: C1-DO2 | D38: NI 9476 (D-Sub) | F38: HYD-HD-DVL-B-170 | G38: <Default>... | H38: Secondary High Speed|Release trigger | I38: S18, S20, S22, S24 | J38: S8.2, S8.4, S8.6, S8.8
A39: ... | B39: Digital PLC output | C39: C1-DO1 | D39: NI 9476 (D-Sub) | F39: HYD-HD-DVL-B-171 | G39: <Default>... | H39: Slow Extend|HD1 | I39: S25.1 | J39: S9.1
A40: ... | B40: Digital PLC output | C40: C1-DO1 | D40: NI 9476 (D-Sub) | F40: HYD-HD-DVL-B-172 | G40: <Default>... | H40: Slow Extend|HD2 | I40: S26.1 | J40: S9.2
...

Sheet Review
A1: =HYPERLINK("https://drive.google.com/open?id=195ADsPF7e6qp-XCMHU02_gGfLOsAuj4y","Link to Drawing") -> Link to Drawing
A2: Review Notes
A3: Reference
A4: By: | B4: Dave Sheerin / Ian Curtis | F4: Date | G4: 43551
A6: Document/Section Reference | B6: Subsection Reference | C6: Find Number (if known) | D6: Comment | I6: Resolution (Accept/Accept w/ Comment/Reject/Withdrawn) | K6: fix notes
A7: LOX | D7: 02CXXX4 to become 02C382 is missing. This is a Proportional valve LO2 Flow Control Skid MARS|C2 Top Return Line Pr Valve | I7: Fixed JP 01/04/2019
A8: LOX | D8: 02Cxxx2 to become 02C383 is missing. This was a DV and is now a Proportional valve LO2 Flow Control Skid MARS|C3 Top Return Line Pr Valve | I8: Fixed JP 01/04/2019
A9: LOX | D9: 02CXXX1 Tank 1, Skid 2. Still to be labeled by GP. This became 02C348 | I9: Fixed JP 01/04/2020
A10: LOX | D10: 02CXXX3 Tank 2, Skid 1 Still to be labeled by GP. This became 02C349 | I10: Fixed JP 01/04/2020
A11: LOX | D11: 02C331, functional purpose was changed and is now up to date in the component description | I11: Fixed - DS 27/03/2019
A12: LOX | D12: 02C331, functional purpose was changed and is now up to date in the component description | I12: Fixed - DS 27/03/2019
A13: LOX | D13: 02Cxxx8, is a PV to become 02C384. This is near the S1 umbilcal. So should come from to electrical vault and it's DI's to go back to CB3 | I13: Fixed JP 01/04/2019
A14: LOX | D14: 02C334, location is not here. Move to ground by erector. So control box is in the electrical vault | I14: Fixed-I/O moved to CB1 JP 29/03/19
A15: LOX | D15: 02C335 is in the strongback. Move IO's as needed. | I15: Fixed- Input CB5, Output CB1 JP 28/03/19
A16: LOX | D16: 02C336 wrong location should be in SB | I16: Fixed- Input CB5, Output CB1 JP 01/04/19
A17: LOX | D17: 02C337 Wrong Location. Move to ground by erector. So the electrical vault is it's source/destination | I17: Fixed in drawings- JP 28/03/19
A18: LOX | D18: 02C338 is in the strongback. Move IO's as needed. | I18: Fixed-Input CB5, Output CB1 JP 28/03/19
... A36: LOX | D36: 02CXXX14 To be added. LO2 Strongback Vent Temp Sensor | I36: Added JP 01/04/2019
A37: GHe | C37: 04C706- CB3 | D37: =HYPERLINK("https://www.dakotainstruments.com/media/docs/Dakota_6AGM_Mass_Flow_Meter_Manual.pdf","04C706 Missing. 4-20mA") -> 04C706 Missing. 4-20mA | I37: Added JP 02/04/2019 New Card AI15
A38: GHe | C38: 04C707- CB3 | D38: =HYPERLINK("https://www.dakotainstruments.com/media/docs/Dakota_6AGM_Mass_Flow_Meter_Manual.pdf","04C707 Missing. 4-20mA") -> 04C707 Missing. 4-20mA | I38: Added JP 02/04/2019 New Card AI15
A39: Elec | C39: XXXX | D39: =HYPERLINK("https://www.ifm.com/us/en/product/IG6083","Inductive Proximity Sensor not in the S1 head- analog input CB3. Use the attached link for the prox") -> Inductive Proximity Sensor not in the S1 head- analog input CB3. Use the attached link for the prox | I39: ADDED BUT NEEDS TO BE DEFINED GK 18/04/2019
A40: ECS | D40: Temp Sensors ECS at the S1 & S2 heads?. They may be ts-117 and 118
A41: LOX | C41: 02C701 | D41: 02C701 will now be modbus | I41: Fixed JP 28/03/19
A42: LOX | C42: 02C705 | D42: 02C705 will now be modbus | I42: Fixed JP 28/03/19
A43: RP1 | C43: 01C705 | D43: 01C705, missing from SWE. Is also using Modbus | I43: Fixed JP 04/04/2019
A44: ECS/HVAC | C44: 05C708 | D44: 05C708, missing from SWE. Likely to me 4-20mA. Goes back to the elec vault | I44: ADDED TO CB2 29/03/19
A45: ECS/HVAC | C45: 05C709 | D45: 05C709, missing from SWE. Likely to me 4-20mA. Goes back to the elec vault | I45: ADDED TO CB2 29/03/19
A46: ECS/HVAC | C46: 05C710 | D46: 05C710, missing from SWE. Likely to me 4-20mA. Goes back to the elec vault | I46: ADDED TO CB2 29/03/19
A47: ECS/HVAC | C47: 05C711 | D47: 05C711, missing from SWE. Likely to me 4-20mA. Goes back to the elec vault | I47: ADDED TO CB2 29/03/19
A48: ECS/HVAC | C48: Chromalux Controls S1 | D48: Chromalux Controls S1. Create a black box for these. See the IO list for the outputs to the Chromalux Control Box (CB10) | I48: 100% done
A49: ECS/HVAC | C49: Chromalux Controls IS1 | D49: Chromalux Controls IS1. Create a black box for these. See the IO list for the outputs to the Chromalux Control Box (CB10) | I49: 100% done
A50: ECS/HVAC | C50: Chromalux Controls IS2 | D50: Chromalux Controls IS2. Create a black box for these. See the IO list for the outputs to the Chromalux Control Box (CB10) | I50: 100% done
A51: ECS/HVAC | C51: Chromalux Controls Fairing | D51: Chromalux Controls Fairing. Create a black box for these. See the IO list for the outputs to the Chromalux Control Box (CB10) | I51: 100% done
A52: Deluge | C52: 41C305 | D52: Don't change but label as (For Future) | I52: Fixed JP 04/04/2019
... A73: GHe/AntiGeysering | C73: 04c346 | D73: Need DI feedbacks. Back to CB3 | I73: Fixed JP 04/04/2019
A74: VSDs/VFDs | B74: LOx Motor Speed Control | C74: 02CXXX (LO2 Pump 1), 02CXXX (LO2 Pump 2) | D74: All VSDs need the following signalling Speed set point 4-20mA (AO) Speed feed fack 4-20mA (AI) Enable signal 24V (DO) Fault Indication 24V (DI) | I74: Added JO 03/04/2019
A75: GOX | B75: can be fixed by just changing names rather than relocaion of components | C75: 05C315 | D75: This is in SWE but no longer in P&ID. Delete name but keep component and wiring for something else | I75: Removed JP 04/04/2019
A76: CH4 | B76: can be fixed by just changing names rather than relocaion of components | C76: 05C322 | D76: This is in SWE but no longer in P&ID. Delete name but keep component and wiring for something else | I76: Removed JP 04/04/2019
A77: GOX | B77: can be fixed by just changing names rather than relocaion of components | C77: 15C314 | D77: Change to 15C380 and update description to GOX Ignitor Upstream Vent Return Solenoid | I77: DS 03/04/2019
A78: GOX | B78: can be fixed by just changing names rather than relocaion of components | C78: 15C311 | D78: Change location to gas pad. Update descrption | I78: DS 03/04/2019
...

Sheet Rev 8 Changes
A1: Rev 8 changes | B1: Scheme Altered | C1: Find Number (If applicable) | D1: Comment | E1: Completed by
B2: Scheme 35 | C2: DC106 | D2: Changed a terminal | E2: DS 09/10/2019
B3: F | C3: 05C970,971,972 | D3: Additions for the Fairing ECS Umbilical | E3: DS 09/10/2019
B4: Scheme 183 &169 | D4: Change of the location of the PT-3 sensor from CB5 to CB4 | E4: DS 15/10/2019
B5: Scheme 102 | C5: 05C945 | D5: IO Channel Name Correction | E5: DS 15/10/2019
B6: Scheme 102 | C6: 05C940 | D6: IO Channel Name Correction | E6: DS 15/10/2019
B7: Scheme 101 | C7: 05C941 | D7: IO Channel Name Correction | E7: DS 15/10/2019
B8: Scheme 101 | C8: 05C942 | D8: IO Channel Name Correction | E8: DS 15/10/2019
B9: Scheme 101 | C9: 05C943 | D9: IO Channel Name Correction | E9: DS 15/10/2019
B10: Scheme 142 | C10: 02C384 | D10: IO Channel Name Correction | E10: DS 15/10/2019
B11: Scheme 143 | C11: 05C934 | D11: IO Channel Name Correction | E11: DS 15/10/2019
B12: Scheme 252 | C12: DC01-AVR01 | D12: Rearranged the block layout to keep sequential | E12: DS 15/10/2019
B13: Scheme 252 | C13: DC106 | D13: Reordered to be in sequence. Reallocated term 7, 8 and 9. To 6,7,8 respectively | E13: DS 15/10/2019
B14: Scheme 252 | C14: DC105 | D14: Inserted Spare blocks to keep this block sequential | E14: DS 15/10/2019
B15: Scheme 253 | C15: CB3.DC350 | D15: Added the full marshalling strip for WCCB3/S1-1 and made the block sequential | E15: DS 15/10/2019
B16: Scheme 253 | C16: CB3.DC350 | D16: Need to find space to physically insert extra terminals in the panel
B17: Scheme 254 | C17: CB4.DC-DI3 | D17: Rearranged the block layout to keep sequential | E17: DS 15/10/2019
B18: Scheme 256 | C18: CB6.DC650 | D18: Rearranged the block layout to keep sequential | E18: DS 15/10/2019
B19: Scheme 258 | C19: CB8.DC801 | D19: Added spare blocks to account for missing numbering & rearranged to make numbering sequential. | E19: DS 15/10/2019
B20: Scheme 259 | C20: CB9.DC118 | D20: Rearranged the block layout to keep sequential | E20: DS 15/10/2019
B21: Scheme 111 | C21: F1, F2, F3. F4 | D21: PNs and terminals clarified | E21: DS 15/10/2019
B22: Scheme 175 | C22: F5 | D22: PNs and terminals clarified | E22: DS 15/10/2019
B23: Scheme 193 | C23: Stage 1 Umbilical | D23: Full schematic of S1U box has been designed. This is the responsibility of RL to build | E23: DS 15/10/2019
B24: Scheme 252 | C24: CB1.DC-AI17 | D24: This has been incorrectly physically labelled as AI7. Needs to be changed in the field to AI17.
B25: Scheme 253 | C25: CB3.DC-AI15 | D25: Rearranged the drawing to match the as built | E25: DS 15/10/2019
B26: Scheme 253 | C26: CB3.DC300 | D26: There are wrong labels on the wiring
B27: Scheme 253 | C27: CB3.DC301 | D27: There are wrong labels on the wiring
B28: Scheme 253 | C28: CB3.DC302 | D28: Some terminals are missing from the as built 31ISO006 & 31ISO009 are also missing
B29: Scheme 254 | C29: CB4.DC450 | D29: Added blocks to match the as built | E29: DS 18/10/2019
B30: Scheme 254 | C30: FX21,22,23,24 | D30: Added blocks to match the as built | E30: DS 18/10/2019
B31: Scheme 253 | C31: CB1.DC-AI1 & AI2 | D31: Rearranged the drawing to match the as built | E31: DS 18/10/2019
B32: Scheme 189 | C32: DC550 | D32: Rearranged for +ve to be on the top rail and 3 additional blocks added | E32: DS 16/10/2019
B33: Scheme 189 | D33: Removed components not being used. Were listed as spare | E33: DS 16/10/2019
B34: Scheme 46 | D34: Proximity sensors were changed to IF505A type. | E34: DS 09/10/2019
D35: As a result 31ISO005 and 31ISO310 were bypassed.
D36: Terminals were changed to 3 tier.
D37: Cable changed to Haz C1D2 M12 cable
B38: Scheme 37 | C38: 05C392 | D38: Find number assigned | E38: DS 09/10/2019
B39: Scheme 39 | C39: 05C392 | D39: Find number assigned | E39: DS 09/10/2019
B40: Scheme 42 | C40: 05C390, 391 | D40: Find number assigned | E40: DS 09/10/2019
...

Sheet IS Review
A1: =HYPERLINK("https://drive.google.com/open?id=195ADsPF7e6qp-XCMHU02_gGfLOsAuj4y","Link to Drawing") -> Link to Drawing
A2: Review Notes
A3: Reference
A4: By: | B4: Dave Sheerin / Ian Curtis | F4: Date | G4: 43551
A6: Document/Section Reference | B6: Subsection Reference | C6: Find Number (if known) | D6: Comment | I6: Resolution (Accept/Accept w/ Comment/Reject/Withdrawn)
C7: BOM for IS devices | D7: 2200BGG200H23DA - This is general use: not Intrinsically Safe - please review BOM LC-2 BOM Rev 3 5-29-19(1)
D8: All the Proportional Directional Valves on the erector need their names to be checked against the hydraulics BOM
C11: 13C961 | D11: IS Barriers added | I11: Done GK 17/06/2019
C12: 13C901 | D12: IS Barriers added | I12: Done GK 17/06/2019
C13: 15C906 | D13: IS Barriers added | I13: Done GK 17/06/2019
C14: 15C907 | D14: IS Barriers added | I14: Done GK 17/06/2019
C15: 15C961 | D15: IS Barriers added | I15: Done GK 17/06/2019
C16: 15C908 | D16: IS Barriers added | I16: Done GK 17/06/2019
C17: 05C909 | D17: IS Barriers added | I17: Done GK 17/06/2019
C18: 14C911 | D18: IS Barriers added | I18: Done GK 17/06/2019
C19: 14C912 | D19: IS Barriers added | I19: Done GK 17/06/2019
C20: 14C913 | D20: IS Barriers added | I20: Done GK 17/06/2019
C21: 14C969 | D21: IS Barriers added | I21: Done GK 17/06/2019
C22: 05C914 | D22: IS Barriers added | I22: Done GK 17/06/2019
... C58: 41C905 | D58: IS Barriers added - - Component part not IS device | I58: Done GK 18/06/2019
C59: 41C999 | D59: Component part not IS device - not in P&ID -
C60: 41C998 | D60: Component part not IS device - not in P&ID -
C61: 41C997 | D61: Component part not IS device - not in P&ID -
C62: 41C303.2 | D62: IS Barriers added | I62: Done GK 21/06/2019
C63: 02C329.2 | D63: IS Barriers added | I63: Done GK 21/06/2019
C64: 02C331.2 | D64: IS Barriers added | I64: Done GK 21/06/2019
C65: 02C332.2 | D65: IS Barriers added | I65: Done GK 21/06/2019
C66: 02C333.2 | D66: IS Barriers added | I66: Done GK 21/06/2019
C67: 02C337.2 | D67: IS Barriers added | I67: Done GK 21/06/2019
C68: 02C338.2 | D68: IS Barriers added | I68: Done GK 21/06/2019
C69: 02C345.2 | D69: IS Barriers added | I69: Done GK 21/06/2019
C70: 02C346.2 | D70: IS Barriers added | I70: Done GK 24/06/2019
C71: 02C384.2 | D71: IS Barriers added | I71: Done GK 24/06/2019
C72: 02C382.2 | D72: IS Barriers added | I72: Done GK 24/06/2019
C73: 02C383.2 | D73: IS Barriers added | I73: Done GK 24/06/2019
... C83: 03C350.2 | D83: IS Barriers added | I83: Done GK 24/06/2019

Sheet Cable List Rev1
A1: Mark | B1: Description | C1: Path | D1: Origin | E1: Destination | F1: Reference
A2: ETH1-CB2 | B2: Network | C2: C.A.CB2<>C.A.CB1 | D2: CB2 - Control Box 2 | E2: CB1 - Control Box 1 | F2: 4C-CAT6e
A3: ETH1-CB1 | B3: Network | C3: C.A.CB1<>C.A.CB1 | D3: CB1 - Control Box 1 | E3: CB1 - Control Box 1 | F3: 4C-CAT6e
A4: ETH2-CB7 | B4: Network | C4: C.A.CB1<>C.CB7 | D4: CB1 - Control Box 1 | E4: CB7 Control Box | F4: 4C-CAT6e
A5: ETH2-CB2 | B5: Network | C5: C.A.CB2<>C.A.CB1 | D5: CB2 - Control Box 2 | E5: CB1 - Control Box 1 | F5: 4C-CAT6e
A6: ETH1-CB3 | B6: Network | C6: C.A.CB1<>C.D.CB3 | D6: CB1 - Control Box 1 | E6: CB3 - Control Box 3 | F6: 4C-CAT6e
A7: ETH2-CB1 | B7: Network | C7: C.A.CB1<>C.A.CB1 | D7: CB1 - Control Box 1 | E7: CB1 - Control Box 1 | F7: 4C-CAT6e
A8: ETH1-CB5 | B8: Network | C8: C.A.CB1<>C.D.CB5 | D8: CB1 - Control Box 1 | E8: Strongback | F8: 4C-CAT6e
A9: ETH1-CB4 | B9: Network | C9: C.A.CB1<>C.D.CB4 | D9: CB1 - Control Box 1 | E9: CB4 - Control Box 4 | F9: 4C-CAT6e
A10: ETH2-CB3 | B10: Network | C10: C.D.CB3<>C.A.CB1 | D10: CB3 - Control Box 3 | E10: CB1 - Control Box 1 | F10: 4C-CAT6e
A11: ETH2-CB5 | B11: Network | C11: C.D.CB5<>C.A.CB1 | D11: Strongback | E11: CB1 - Control Box 1 | F11: 4C-CAT6e
A12: ETH1-CB6 | B12: Network | C12: C.A.CB1<>C.E.CB6 | D12: CB1 - Control Box 1 | E12: CB6 - Control Box 6 | F12: 4C-CAT6e
... A16: WCCB3-30 | B16: 4 Core Pressure Transducer Wire Assy | C16: C.B<>C.B | D16: LOx Area | E16: LOx Area | F16: 4x 0.33
A17: WCLIENT-3 | B17: UNITRONIC PUR CP (TP) 3 x 2 x 0.25 | C17: C.A.L<>C.D.R | D17: Client Room | E17: Client Panel | F17: 32851
A18: WCLIENT-4 | B18: UNITRONIC PUR CP (TP) 3 x 2 x 0.25 | C18: C.A.L<>C.D.R | D18: Client Room | E18: Client Panel | F18: 32851
A19: WCCB3/F2-5 | B19: 4 Core Power Cable | C19: C.D.CB3<>C.D.F2 | D19: CB3 - Control Box 3 | E19: Erector | F19: 1000 R2V-RH 4X4 M
A20: WCCB4/F3-03 | B20: 4 Core Power Cable | C20: C.D.CB4<>C.D.F3 | D20: CB4 - Control Box 4 | E20: Erector | F20: 1000 R2V-RH 4X4 M
A21: WCAVR/CB5-4 | B21: 18 Core Instrumentation Cable | C21: C.A<>C.D.CB5 | D21: Electrical Vault | E21: Strongback | F21: 18G 0.75
A22: WCAVR/F8-4 | B22: 18 Core Instrumentation Cable | C22: C.A<>C.D.F4 | D22: Electrical Vault | E22: GNC BOX | F22: 18G 0.75
A23: WCCB1/CB3-1 | B23: 18 Core Instrumentation Cable | C23: C.A.CB1<>C.D.CB3 | D23: CB1 - Control Box 1 | E23: CB3 - Control Box 3 | F23: 18G 0.75
A24: WCCB1/CB3-2 | B24: 18 Core Instrumentation Cable | C24: C.A.CB1<>C.D.CB3 | D24: CB1 - Control Box 1 | E24: CB3 - Control Box 3 | F24: 18G 0.75
A25: WCCB1/CB4-1 | B25: 18 Core Instrumentation Cable | C25: C.A.CB1<>C.D.CB4 | D25: CB1 - Control Box 1 | E25: CB4 - Control Box 4 | F25: 18G 0.75
A26: WCCB1/CB5-1 | B26: 18 Core Instrumentation Cable | C26: C.A.CB1<>C.D.CB5 | D26: CB1 - Control Box 1 | E26: Strongback | F26: 18G 0.75
A27: WCCB1/CB9-1 | B27: 18 Core Instrumentation Cable | C27: C.A.CB1<>C.D.CB9 | D27: CB1 - Control Box 1 | E27: Erector | F27: 18G 0.75
A28: WCCB1/F1-1 | B28: 18 Core Instrumentation Cable | C28: C.A.CB1<>C.A.F1 | D28: CB1 - Control Box 1 | E28: Gas Storage | F28: 18G 0.75
A29: WCCB1/F2-1 | B29: 18 Core Instrumentation Cable | C29: C.A.CB1<>C.D.F2 | D29: CB1 - Control Box 1 | E29: Erector | F29: 18G 0.75
A30: WCCB1/F2-2 | B30: 18 Core Instrumentation Cable | C30: C.A.CB1<>C.D.F2 | D30: CB1 - Control Box 1 | E30: Erector | F30: 18G 0.75
... A120: WCCB2-20 | B120: 4 Core Instrumentation Cable | C120: C.D<>C.A.CB2 | D120: Erector | E120: CB2 - Control Box 2 | F120: 4 X 0.75
A121: WCCB2/F2-1 | B121: 4 Core Instrumentation Cable | C121: C.A.CB2<>C.D.F2 | D121: CB2 - Control Box 2 | F121: 4 X 0.75
A122: WCCB3-1 | B122: 4 Core Instrumentation Cable | C122: C.D<>C.D.CB3 | D122: Erector | E122: CB3 - Control Box 3 | F122: 4 X 0.75
A123: WCCB3-2 | B123: 4 Core Instrumentation Cable | C123: C.E<>C.D.CB3 | D123: Equipment Vault | E123: CB3 - Control Box 3 | F123: 4 X 0.75
A124: WCCB3-3 | B124: 4 Core Instrumentation Cable | C124: C.D<>C.D.CB3 | D124: Erector | E124: CB3 - Control Box 3 | F124: 4 X 0.75
A125: WCCB3-4 | B125: 4 Core Instrumentation Cable | C125: C.D.CB3<>C.D.CB3 | D125: CB3 - Control Box 3 | E125: CB3 - Control Box 3 | F125: 4 X 0.75
A126: WCCB3-5 | B126: 4 Core Instrumentation Cable | C126: C<>C.D.CB3 | D126: Pad 0C | E126: CB3 - Control Box 3 | F126: 4 X 0.75
A127: WCCB3-6 | B127: 4 Core Instrumentation Cable | C127: C<>C.D.CB3 | D127: Pad 0C | E127: CB3 - Control Box 3 | F127: 4 X 0.75
A128: WCCB3-7 | B128: 4 Core Instrumentation Cable | C128: C<>C.D.CB3 | D128: Pad 0C | E128: CB3 - Control Box 3 | F128: 4 X 0.75
A129: WCCB3-8 | B129: 4 Core Instrumentation Cable | C129: C<>C.D.CB3 | D129: Pad 0C | E129: CB3 - Control Box 3 | F129: 4 X 0.75
A130: WCCB3-9 | B130: 4 Core Instrumentation Cable | C130: C.D.CB3<>C.D.CB3 | D130: CB3 - Control Box 3 | E130: CB3 - Control Box 3 | F130: 4 X 0.75
A131: WCCB3-10 | B131: 4 Core Instrumentation Cable | C131: C.D.CB3<>C | D131: CB3 - Control Box 3 | E131: Pad 0C | F131: 4 X 0.75
A132: WCCB3-11 | B132: 4 Core Instrumentation Cable | C132: C.D.CB3<>C.D.CB3 | D132: CB3 - Control Box 3 | E132: CB3 - Control Box 3 | F132: 4 X 0.75
...

Sheet Cable List Rev2
A1: Mark | B1: Description | C1: Path | D1: Origin | E1: Destination | F1: Reference
A2: CB1/CB2-0VDC1 | B2: 0V dc Ring | C2: C.A.CB1.CB2<>C.A.CB1 | D2: CB2 - Control Box 2 | E2: CB1 - Control Box 1 | F2: 1026513
A3: CB1/CB3-0VDC | B3: 0V dc Ring | C3: C.D.CB3<>C.D.CB3 | D3: CB3 - Control Box 3 | E3: CB3 - Control Box 3 | F3: 1026513
A4: CB1/CB4-0VDC | B4: 0V dc Ring | C4: C.A.CB1<>C.D.CB4 | D4: CB1 - Control Box 1 | E4: CB4 - Control Box 4 | F4: 1026513
A5: CB1/F1-0VDC | B5: 0V dc Ring | C5: C.A.CB1<>C.F1 | D5: CB1 - Control Box 1 | E5: South Gas Pad | F5: 1026513
A6: CB3/CB9-0VDC | B6: 0V dc Ring | C6: C.D.CB3<>C.D.CB9 | D6: CB3 - Control Box 3 | E6: Battery Heater | F6: 1026513
A7: CB3/F2-0VDC | B7: 0V dc Ring | C7: C.D.CB3<>C.D.F2 | D7: CB3 - Control Box 3 | E7: Erector South East | F7: 1026513
A8: CB4/F3-0VDC | B8: 0V dc Ring | C8: C.D.CB4<>C.D.F3 | D8: CB4 - Control Box 4 | E8: Erector North East | F8: 1026513
A9: CB4/F3-0VDC | B9: 0V dc Ring | C9: C.D.F3<>C.D.CB4 | D9: Erector North East | E9: CB4 - Control Box 4 | F9: 1026513
A10: CB6/CB7-0VDC | B10: 0V dc Ring | C10: C.E.CB6<>C.CB7 | D10: CB6 - Control Box 6 | E10: CB7 Control Box | F10: 1026513
A11: CB6/F5-0VDC | B11: 0V dc Ring | C11: C.E.CB6<>C.F5 | D11: CB6 - Control Box 6 | E11: Helium Pad | F11: 1026513
A12: CB9/CB4-0VDC | B12: 0V dc Ring | C12: C.D.CB9<>C.D.CB4 | D12: Battery Heater | E12: CB4 - Control Box 4 | F12: 1026513
A13: F2/CB5-0VDC | B13: 0V dc Ring | C13: C.D.F2<>C.D.J.CB5 | D13: Erector South East | E13: Strongback | F13: 1026513
... A15: F5/F6-0VDC | B15: 0V dc Ring | C15: C.F6<>C.F5 | D15: High Pressure GHE/GN2 | E15: Helium Pad | F15: 1026513
A16: WCCB1/CB3-1 | B16: 18 Core Instrumentation Cable | C16: C.A.CB1<>C.D.CB3 | D16: CB1 - Control Box 1 | E16: CB3 - Control Box 3 | F16: 18G 0.75
A17: WCCB1/CB3-2 | B17: 18 Core Instrumentation Cable | C17: C.A.CB1<>C.D.CB3 | D17: CB1 - Control Box 1 | E17: CB3 - Control Box 3 | F17: 18G 0.75
A18: WCCB1/CB4-1 | B18: 18 Core Instrumentation Cable | C18: C.A.CB1<>C.D.CB4 | D18: CB1 - Control Box 1 | E18: CB4 - Control Box 4 | F18: 18G 0.75
A19: WCCB1/CB4-2 | B19: 18 Core Instrumentation Cable | C19: C.A.CB1<>C.D.CB4 | D19: CB1 - Control Box 1 | E19: CB4 - Control Box 4 | F19: 18G 0.75
A20: WCCB1/CB5-1 | B20: 18 Core Instrumentation Cable | C20: C.A.CB1<>C.D.J.CB5 | D20: CB1 - Control Box 1 | E20: Strongback | F20: 18G 0.75
A21: WCCB1/CB9-1 | B21: 18 Core Instrumentation Cable | C21: C.A.CB1<>C.D.CB9 | D21: CB1 - Control Box 1 | E21: Battery Heater | F21: 18G 0.75
A22: WCCB1/F1-1 | B22: 18 Core Instrumentation Cable | C22: C.A.CB1<>C.F1 | D22: CB1 - Control Box 1 | E22: South Gas Pad | F22: 18G 0.75
A23: WCCB1/F2-1 | B23: 18 Core Instrumentation Cable | C23: C.A.CB1<>C.D.F2 | D23: CB1 - Control Box 1 | E23: Erector South East | F23: 18G 0.75
A24: WCCB1/F2-2 | B24: 18 Core Instrumentation Cable | C24: C.A.CB1<>C.D.F2 | D24: CB1 - Control Box 1 | E24: Erector South East | F24: 18G 0.75
A25: WCCB1/F2-3 | B25: 18 Core Instrumentation Cable | C25: C.A.CB1<>C.D.F2 | D25: CB1 - Control Box 1 | E25: Erector South East | F25: 18G 0.75
A26: WCCB1/F3-1 | B26: 18 Core Instrumentation Cable | C26: C.A.CB1<>C.D.F3 | D26: CB1 - Control Box 1 | E26: Erector North East | F26: 18G 0.75
A27: WCCB1/S2-1 | B27: 18 Core Instrumentation Cable | C27: C.A.CB1<>C.D.J.S2_BOX | D27: CB1 - Control Box 1 | E27: STRONG BACK STAGE 2 BOX | F27: 18G 0.75
... A469: WCAVR/F8-3 | B469: Supply | C469: C.A<>C.D.F4 | D469: Electrical Vault | E469: GNC BOX | F469: 4G 16

Sheet Drawing Status
A1: System | C1: 1st Draft Elec Drawings Done | D1: Final P&IDs Received | E1: Date | F1: 1st Review Done | H1: Alterations Complete | I1: 2nd Review done | J1: Check Schematics | K1: Complete for release
A2: Description | B2: Number | F2: Complete? | G2: By
A3: LC-2 GN2 UTILITY SKID | B3: MP-101 | C3: YES | D3: YES | E3: 43559 | F3: YES | G3: DS | H3: YES
A4: MUSCLE GASEOUS NITROGEN (GN2) | B4: MP-102 | C4: YES | D4: YES | E4: 43559 | F4: YES | G4: DS | H4: YES
A5: INSTRUMENT GASEOUS NITROGEN (GN2) | B5: MP-103 | C5: YES | D5: YES | E5: 43559 | F5: YES | G5: DS | H5: N/A Covered Elsewhere
A6: LO2 STORAGE SCHEMATIC | B6: MP-104 | C6: YES | D6: YES | E6: 43559 | F6: YES | G6: JP | H6: YES
A7: LOX SCHEMATIC | B7: MP-105 | C7: YES | D7: YES | E7: 43559 | F7: YES | G7: JP | H7: YES
A8: GASEOUS OXYGEN (GOX) | B8: MP-106 | C8: YES | D8: YES | E8: 43557 | F8: YES | G8: DS | H8: YES
A9: METHANE (CH4) | B9: MP-107 | C9: YES | D9: YES | E9: 43557 | F9: YES | G9: DS | H9: YES
A10: ROCKET PROPELLANT 1 (RP1) | B10: MP-108 | C10: YES | D10: YES | E10: 43557 | F10: YES | G10: DS | H10: YES
A11: HVAC / ECS | B11: MP-109 | C11: YES | D11: YES | E11: 43566 | F11: YES | G11: DS | H11: NO
A12: CARBON DIOXIDE | B12: MP-110 | C12: YES | D12: YES | E12: 43557 | F12: YES | G12: DS | H12: YES
A13: DELUGE | B13: MP-111 | C13: YES | D13: YES | E13: 43557 | F13: YES | G13: DS | H13: YES
A14: MEDIUM PRESSURE GHe (ANTI-GEYSERING) | B14: MP-112 | C14: YES | D14: YES | E14: 43557 | F14: YES | G14: DS | H14: YES
A15: ERECTOR GN2 PURGE GAS | B15: MP-113 | C15: YES | D15: YES | E15: 43572 | F15: YES | G15: JP | H15: NO
A16: GN2 / KERO PURGE STAGE 1 | B16: MP-114 | C16: YES | D16: YES | E16: 43572 | F16: NO | H16: NO
A17: GN2 / KERO PURGE STAGE 2 | B17: MP-115 | C17: YES | D17: YES | E17: 43572 | F17: YES | G17: GK | H17: NO
A18: GN2 (HIGH FLOW) | B18: MP-116 | C18: YES | D18: YES | E18: 43584 | F18: YES | G18: JO | H18: NO
A19: GN2 - LOX PURGE | B19: MP-117 | C19: YES | D19: YES | E19: 43572 | F19: NO | H19: NO
A20: STRONG BACK | B20: MP-118 | C20: YES | D20: YES | E20: 43572 | F20: NO | H20: NO
A21: STAGE 1 UMBILICAL | B21: MP-119 | C21: YES | D21: YES | E21: 43572 | F21: N/A Covered Elsewhere | G21: JO | H21: NO
A22: EJECTION / JETTISON GN2 | B22: MP-120 | C22: YES | D22: YES | E22: 43572 | F22: NO | H22: NO
A23: STAGE 2 UMBILICAL | B23: MP-121 | C23: YES | D23: YES | E23: 43572 | F23: YES | G23: JO | H23: NO
A24: Hydraulics | B24: RevD | C24: YES | D24: YES | E24: 43556 | F24: YES | G24: JO | H24: YES
A25: STAGE 3 (Fairing) HVAC | C25: YES | D25: NO | F25: NO | G25: JO | H25: NO

Sheet ECS Heater Control Review 
A2: Signal | B2: Type | C2: Chromalox Terminal
A3: Power Pack Heater Enable (24V = Enabled) | B3: Digital Output (24V) | C3: TB1-9, TB1-10 | G3: integrated into Chromalux's panel
A4: Power Pack Heater Trip Reset 24V to reset | B4: Digital Output (24V) | C4: Main Control Board: J3-6, J3-5 | G4: Into TIC terminal 8 and 9
A5: Power Pack Heater Mode (24V = PID mode, 0V = demand mode) | B5: Digital Output (24V) | C5: ?, ? | G5: Into TIC terminal 7 and 6
A6: Setpoint 4-20mA (0-100 degrees C) | B6: Analog Output (4-20mA, sourcing) | C6: TIC1-7, TIC1-6 | G6: Not clear in drawings how we can directly trigger the scr. Do we need a 4-20mA isolating device as it appears they need the signal to be sourced from their control unit?
A7: Heater Process Temperature 4-20mA (-50 to 150 degrees C) | B7: Analog Input (4-20mA, sinking) | C7: ?, ?
A8: overtemp trip (0V = trip) | B8: Digital Input (24V) | C8: TB2-1, TB2-12 (TB2-2 to TB2-11 wired in series) | G8: Not clear in drawings how we can directly trigger the scr. Do we need a 4-20mA isolating device as it appears they need the signal to be sourced from their control unit?
G13: What connections does he expect to the controllers. And shouldn't they be connected to terminal strips? The way it is drawn we would have to wire directly into the controllers. We need to control the set points mentioned in A4-A10
A15: Drawing Number | E15: Abbreviation | F15: Description | G15: PN
A16: 8405-3480100-1014966-5 | E16: TIC | F16: Temperature Controller | G16: =HYPERLINK("http://www.chromalox.com/catalog/resources/IM-PK508.pdf","4040-ARA110") -> 4040-ARA110
E17: OTC | F17: Overtemp Control | G17: =HYPERLINK("http://www.chromalox.com/catalog/resources/MOD-6050-4050.pdf","6050-1RA10") -> 6050-1RA10
E18: SCR | F18: SCR | G18: MMAX2-401110-0001

Sheet Fusing
A1: Fuse Code | B1: Fuse Number | C1: Term Strip Number | D1: System Description | E1: Location | G1: Number of fuse blocks
A2: =CONCATENATE("F",B2) -> F1.1 | B2: 1.1 | C2: FX01 | D2: Internal Componentry | E2: South Vault | G2: South Vault | H2: North Vault | I2: RP-1 skid | J2: LOX skid
A3: =CONCATENATE("F",B3) -> F1.2 | B3: 1.2 | C3: FX02 | D3: Hydraulics 1 | E3: South Vault | G3: =ROUNDUP(COUNTIF($E:$E,G2)/4,1) -> 7.8 | H3: =ROUNDUP(COUNTIF($E:$E,H2)/4,1) -> 1 | I3: =ROUNDUP(COUNTIF($E:$E,I2)/4,1) -> 1 | J3: =ROUNDUP(COUNTIF($E:$E,J2)/4,1) -> 1
A4: =CONCATENATE("F",B4) -> F1.3 | B4: 1.3 | C4: FX03 | D4: Hydraulics 2 | E4: South Vault
A5: =CONCATENATE("F",B5) -> F1.4 | B5: 1.4 | C5: FX04 | D5: Lox Erector platorm launcher | E5: South Vault
A6: =CONCATENATE("F",B6) -> F2.1 | B6: 2.1 | C6: FX05 | D6: ECS 1 | E6: South Vault
A7: =CONCATENATE("F",B7) -> F2.2 | B7: 2.2 | C7: FX06 | D7: ECS 2 | E7: South Vault
A8: =CONCATENATE("F",B8) -> F2.3 | B8: 2.3 | C8: FX07 | D8: Igniter | E8: South Vault
A9: =CONCATENATE("F",B9) -> F2.4 | B9: 2.4 | C9: FX08 | D9: Kero Tank Purge | E9: South Vault
A10: =CONCATENATE("F",B10) -> F3.1 | B10: 3.1 | C10: FX09 | D10: Network | E10: South Vault
A11: =CONCATENATE("F",B11) -> F3.2 | B11: 3.2 | C11: FX10 | D11: Auxiliary | E11: South Vault
A12: =CONCATENATE("F",B12) -> F3.3 | B12: 3.3 | C12: FX11 | D12: Sense A | E12: South Vault
A13: =CONCATENATE("F",B13) -> F3.4 | B13: 3.4 | C13: FX12 | D13: Sense B | E13: South Vault
A14: =CONCATENATE("F",B14) -> F4.1 | B14: 4.1 | C14: FX13 | D14: CB1- Controllers | E14: South Vault
A15: =CONCATENATE("F",B15) -> F4.2 | B15: 4.2 | C15: FX14 | D15: AVR SUPPLY | E15: South Vault
... A29: =CONCATENATE("F",B29) -> F7.4 | B29: 7.4 | C29: FX28 | D29: N4 - Vehicle Services | E29: South Vault
A30: =CONCATENATE("F",B30) -> F8.1 | B30: 8.1 | C30: FX29 | D30: C3 - Place holder | E30: RP-1 skid | F30: CB7
A31: =CONCATENATE("F",B31) -> F8.2 | B31: 8.2 | C31: FX30 | D31: C3 - Place holder | E31: RP-1 skid | F31: CB7
A32: =CONCATENATE("F",B32) -> F8.3 | B32: 8.3 | C32: FX31 | D32: C3 - Place holder | E32: RP-1 skid | F32: CB7
A33: =CONCATENATE("F",B33) -> F8.4 | B33: 8.4 | C33: FX32 | D33: C3 - Place holder | E33: RP-1 skid | F33: CB7
A34: =CONCATENATE("F",B34) -> F9.1 | B34: 9.1 | C34: FX33 | D34: Hydraulics 3
A35: =CONCATENATE("F",B35) -> F9.2 | B35: 9.2 | C35: FX34 | D35: Controller Power Backup
A36: =CONCATENATE("F",B36) -> F9.3 | B36: 9.3 | C36: FX35 | D36: DIO Gating | E36: South Vault
A37: =CONCATENATE("F",B37) -> F9.4 | B37: 9.4 | C37: FX36 | D37: Spare
A38: =CONCATENATE("F",B38) -> F10.1 | B38: 10.1 | C38: FX37 | D38: C2 - Controllers | E38: LOX skid | F38: CB8
A39: =CONCATENATE("F",B39) -> F10.2 | B39: 10.2 | C39: FX38 | D39: C2 - Sense A | E39: LOX skid | F39: CB8
A40: =CONCATENATE("F",B40) -> F10.3 | B40: 10.3 | C40: FX39 | D40: C2 - Sense B | E40: LOX skid | F40: CB8
A41: =CONCATENATE("F",B41) -> F10.4 | B41: 10.4 | C41: FX40 | D41: C2 - Back up | E41: LOX skid | F41: CB8
A42: F11.1 | B42: 11.1 | C42: FX41 | D42: N5 - Controllers | E42: North Vault | F42: CB6
A43: F11.2 | B43: 11.2 | C43: FX42 | D43: N5 - Sense A | E43: North Vault | F43: CB6
A44: F11.3 | B44: 11.3 | C44: FX43 | D44: N5 - Hydraulic Pump 1 | E44: North Vault | F44: CB6
A45: F11.4 | B45: 11.4 | C45: FX44 | D45: N5 - Hydraulic Pump 2 | E45: North Vault | F45: CB6
A46: F12.1 | B46: 11.1 | C46: FX45 | D46: N6 - HVH Controllers | E46: ERECTOR | F46: CB9 | G46: Fed From FX16
A47: F12.2 | B47: 11.2 | C47: FX46 | D47: N6 - HVH Sense A | E47: ERECTOR | F47: CB9
A48: F12.3 | B48: 11.3 | C48: FX47 | D48: N6 - HVH Sense B | E48: ERECTOR | F48: CB9
A49: F12.4 | B49: 11.4 | C49: FX48 | D49: N6 - HVH Back up | E49: ERECTOR | F49: CB9
A50: F12.5 | B50: 11.4 | C50: FX49 | D50: additional sitop in CB1 | E50: South Vault | F50: CB1
A51: F12.6 | B51: 11.4 | C51: FX50 | D51: additional sitop in CB1 | E51: South Vault | F51: CB1

Sheet DC Terminal designations
A1: Dest. Enclosure | B1: DC TERMINAL NAMING CONVENTION
A2: CB1 | B2: DC same naming as designation panels
A3: CB2 | B3: DC same naming as designation panels
A4: AC01 | B4: AC SUPPLY
A5: AC02 | B5: AC MOTOR SUPPLY
A6: AC01 | B6: AC01 | C6: AC SUPPLY
A7: AC02 | B7: AC02 | C7: AC MOTOR SUPPLY
A8: CB9.DC01 | B8: DC01 | C8: HV Batt 2 LEVEL from CB1
A9: CB4.DC01 | B9: DC01 | C9: HYDRAULICS 3 LEVEL TO INST
A10: CB8.DC01 | B10: DC01 | C10: Liquid Oxygen 2 LEVEL
A11: CB3.DC01 | B11: DC01 | C11: IGNITER 2 LEVEL
A12: CB3.DC01 | B12: DC01 | C12: Liquid Oxygen 2 LEVEL
A13: DC01-AVR | B13: DC01-AVR | C13: AV RACK RPSUs CABLE
A14: DC01-AVR01 | B14: DC01-AVR01
A15: CB4.DC02 | B15: DC02 | C15: HYDRAULICS 2 LEVEL FROM CB4
A16: CB1.DC02 | B16: DC02 | C16: HYDRAULICS 2 LEVEL FROM CB4
A17: CB2.DC02 | B17: DC02 | C17: IGNITER 3 LEVEL FROM F1
A18: CB3.DC02 | B18: DC02 | C18: IGNITER 3 LEVEL
A19: CB3.DC03 | B19: DC03 | C19: Liquid Oxygen 2 LEVEL
A20: DC03-AVR01 | B20: DC03-AVR01 | C20: AVR TERMINALS TO ERECTOR
A21: CB4.DC04 | B21: DC04 | C21: HYDRAULICS 3 LEVEL- CB4 To CB1
A22: CB1.DC04 | B22: DC04 | C22: HYDRAULICS 3 LEVELCB1 TO CB4
A23: CB3.DC04 | B23: DC04 | C23: Liquid Oxygen 2 LEVEL
A24: CB1.DC050 | B24: DC050 | C24: WATER DELUGE CONNECTIONS 2 LEVEL
A25: F8.DC0901 | B25: DC0901 | C25: GNC TERMINALS FROM SOUTH VAULT
A26: F8.DC0902 | B26: DC0902 | C26: GNC TERMINALS TO UMBILICAL
... A39: F2.DC201 | B39: DC201 | C39: HYDRAULICS 2 LEVEL FIELD TO CB1
A40: DC202 | B40: DC202
A41: CB3.DC202 | B41: DC202 | C41: HYDRAULICS F2 TO CB3
A42: CB1.DC202 | B42: DC202 | C42: HYDRAULICS 2 LEVEL FROM F2
A43: F2.DC202 | B43: DC202 | C43: HYDRAULICS 2 LEVEL FIELD TO CB1
A44: CB3.DC251 | B44: DC251 | C44: HYDRAULICS 3 LEVEL F2 TO CB3
A45: F2.DC251 | B45: DC251 | C45: HYDRAULICS 3 LEVEL F2 TO CB3
A46: CB4.DC300 | B46: DC300 | C46: HYDRAULICS2 LEVEL F3 TO CB4
A47: F3.DC300 | B47: DC300 | C47: HYDRAULICS 2LEVEL F3 TO CB4
A48: CB1.DC302 | B48: DC302 | C48: HYDRAULICS 2 LEVEL FROM F3
A49: F3.DC302 | B49: DC302 | C49: HYDRAULICS 2 LEVEL F3 TO CB1
A50: CB4.DC350 | B50: DC350 | C50: HYDRAULICS 3 LEVEL- F3 To CB4
A51: F3.DC350 | B51: DC350 | C51: HYDRAULICS 3 LEVEL F3 TO CB4
